#VRML_SIM R2020a utf8
WorldInfo {
}
Viewpoint {
  orientation 0.9213839775283759 -0.3450432388818843 -0.1788762959586549 6.052155298452765
  position 0.07352073222452433 0.24278241435420822 1.1924435968125733
}
TexturedBackground {
}
TexturedBackgroundLight {
}
Robot {
  translation -2.21999 -0.149998 7.08
  rotation 0 0.7071055564400445 0.7071080059309292 2.0944
  children [
    HingeJoint {
      device [
        RotationalMotor {
          name "rotational motor 3"
          acceleration 1.5655595373012297
        }
      ]
      endPoint Solid {
        translation 0 0.64 0
        rotation 1 0 0 0
        children [
          Shape {
            geometry Cylinder {
              height 0.2
              radius 0.05
            }
          }
        ]
        name "solid(2)"
      }
    }
    HingeJoint {
      device [
        RotationalMotor {
          name "rotational motor 2"
          acceleration 0.72241341228803
        }
      ]
      endPoint Solid {
        translation 0 0.43 0
        rotation 1 0 0 0
        children [
          Shape {
            geometry Cylinder {
              height 0.2
              radius 0.05
            }
          }
        ]
        name "solid(1)"
      }
    }
    Shape {
      geometry Cylinder {
        height 0.2
        radius 0.05
      }
    }
    HingeJoint {
      device [
        RotationalMotor {
          name "rotational motor 1"
          acceleration 1.6086232168900203
        }
      ]
      endPoint Solid {
        translation 0 0.22 0
        rotation 1 0 0 0
        children [
          Shape {
            geometry Cylinder {
              height 0.2
              radius 0.05
            }
          }
        ]
      }
    }
  ]
  name "new robot"
  boundingObject Cylinder {
    height 0.2
    radius 0.05
  }
  physics Physics {
  }
  controller "my_controller"
  supervisor TRUE
}
Windmill {
  translation -26.17 -0.54 20.25
}
Robot {
  translation 0 0.01 0
  rotation 1.6952594753969508e-09 0.707104781184338 0.7071087811831002 -3.1415853071795863
  children [
    HingeJoint {
      jointParameters HingeJointParameters {
      }
      device [
        RotationalMotor {
          name "rotational motor 1"
          acceleration 0.02670947683018752
        }
      ]
      endPoint Solid {
        translation 0 0.10598100000000003 0
        rotation 1 0 0 0
        children [
          HingeJoint {
            jointParameters HingeJointParameters {
            }
            device [
              RotationalMotor {
                name "rotational motor 2"
                acceleration 0.5984470727403238
              }
            ]
            endPoint Solid {
              translation 0 0.11 0
              rotation 1 0 0 0
              children [
                HingeJoint {
                  jointParameters HingeJointParameters {
                  }
                  device [
                    RotationalMotor {
                      name "rotational motor 3"
                      acceleration 0.993112818090025
                    }
                  ]
                  endPoint Solid {
                    translation -1.964199712600756e-09 0.11000000000229027 -1.106842716439016e-09
                    rotation 1.29775e-15 -1 3.384709999999999e-14 0.5235953071795861
                    children [
                      Shape {
                        geometry Cylinder {
                          height 0.1
                          radius 0.05
                        }
                      }
                    ]
                    boundingObject Cylinder {
                      height 0.1
                      radius 0.05
                    }
                    physics Physics {
                    }
                  }
                }
                Shape {
                  geometry Cylinder {
                    height 0.1
                    radius 0.05
                  }
                }
              ]
              boundingObject Cylinder {
                height 0.1
                radius 0.05
              }
              physics Physics {
              }
            }
          }
          Shape {
            geometry Cylinder {
              height 0.1
              radius 0.05
            }
          }
        ]
        boundingObject Cylinder {
          height 0.1
          radius 0.05
        }
        physics Physics {
        }
      }
    }
    Shape {
      appearance Appearance {
      }
      geometry Cylinder {
        height 0.1
        radius 0.05
      }
    }
  ]
  boundingObject Cylinder {
    height 0.1
    radius 0.05
  }
  physics Physics {
  }
  controller "my_controller_2"
  supervisor TRUE
}
WoodenBox {
  translation 0 -0.57 0.16
  size 10 1 10
}
