#VRML_SIM R2020a utf8
WorldInfo {
}
Viewpoint {
  orientation 0.08509000241340657 -0.9873930746298206 -0.13347137394346362 4.838985191261026
  position 0.9718723960212539 0.16885418188754406 0.8437341225201747
}
TexturedBackground {
}
TexturedBackgroundLight {
}
Windmill {
  translation -26.17 -0.54 20.25
}
WoodenBox {
  translation 0 -0.57 0.16
  size 10 1 10
}
Robot {
  translation 7.71424e-07 0 0.76
  rotation 0 1 0 1.01503e-06
  children [
    HokuyoUtm30lx {
      translation 0 0.08 0
      name "sensor"
    }
    Shape {
      appearance Appearance {
        material Material {
          diffuseColor 0.666667 0 0
        }
      }
      geometry Box {
        size 0.1 0.05 0.1
      }
    }
    HingeJoint {
      device [
        RotationalMotor {
          name "rotational motor 1"
        }
      ]
      endPoint Solid {
        translation 0 -3.469446951953614e-18 0.10000000000000006
        rotation 1 0 0 0
        children [
          HingeJoint {
            device [
              RotationalMotor {
                name "rotational motor 2"
              }
            ]
            endPoint Solid {
              translation 0 1.734723475976807e-18 0.10000000000000013
              rotation 1 0 0 0
              children [
                HingeJoint {
                  device [
                    RotationalMotor {
                      name "rotational motor 3"
                    }
                  ]
                  endPoint Solid {
                    translation 0 -6.938893903907228e-18 0.10000000000000007
                    rotation 1 0 0 0
                    children [
                      HingeJoint {
                        device [
                          RotationalMotor {
                            name "rotational motor 4"
                          }
                        ]
                        endPoint Solid {
                          translation 0 3.469446951953614e-18 0.10000000000000005
                          rotation 1 0 0 0
                          children [
                            HingeJoint {
                              device [
                                RotationalMotor {
                                  name "rotational motor 5"
                                }
                              ]
                              endPoint Solid {
                                translation 0 -1.8418782124496325e-12 0.10000000000000002
                                rotation 1 0 0 0
                                children [
                                  HingeJoint {
                                    device [
                                      RotationalMotor {
                                        name "rotational motor 6"
                                      }
                                    ]
                                    endPoint Solid {
                                      translation 0 -3.469446951953614e-18 0.1000000000000001
                                      rotation 1 0 0 0
                                      children [
                                        Shape {
                                          geometry Box {
                                            size 0.1 0.05 0.1
                                          }
                                        }
                                      ]
                                      boundingObject Box {
                                        size 0.1 0.05 0.1
                                      }
                                      physics Physics {
                                      }
                                    }
                                  }
                                  Shape {
                                    geometry Box {
                                      size 0.1 0.05 0.1
                                    }
                                  }
                                ]
                                boundingObject Box {
                                  size 0.1 0.05 0.1
                                }
                                physics Physics {
                                }
                              }
                            }
                            Shape {
                              geometry Box {
                                size 0.1 0.05 0.1
                              }
                            }
                          ]
                          boundingObject Box {
                            size 0.1 0.05 0.1
                          }
                          physics Physics {
                          }
                        }
                      }
                      Shape {
                        geometry Box {
                          size 0.1 0.05 0.1
                        }
                      }
                    ]
                    boundingObject Box {
                      size 0.1 0.05 0.1
                    }
                    physics Physics {
                    }
                  }
                }
                Shape {
                  geometry Box {
                    size 0.1 0.05 0.1
                  }
                }
              ]
              boundingObject Box {
                size 0.1 0.05 0.1
              }
              physics Physics {
              }
            }
          }
          Shape {
            geometry Box {
              size 0.1 0.05 0.1
            }
          }
        ]
        boundingObject Box {
          size 0.1 0.05 0.1
        }
        physics Physics {
        }
      }
    }
  ]
  boundingObject Box {
    size 0.1 0.05 0.1
  }
  physics Physics {
  }
  controller "my_controller_2"
  supervisor TRUE
}
CardboardBox {
  translation 0 0.22 -0.68
}
