#VRML_SIM R2020a utf8
WorldInfo {
}
Viewpoint {
  orientation 0.1477118612266436 -0.9678314531722454 -0.20367494765793023 4.536249183395532
  position 1.12962780894581 0.40223956686651746 0.19874582695575485
}
TexturedBackground {
}
TexturedBackgroundLight {
}
Windmill {
  translation -26.17 -0.54 20.25
}
WoodenBox {
  translation 0 -0.57 0.16
  size 10 1 10
}
Robot {
  children [
    Shape {
      geometry Box {
        size 0.1 0.05 0.1
      }
    }
    HingeJoint {
      device [
        RotationalMotor {
          name "rotational motor 1"
        }
      ]
      endPoint Solid {
        translation 0 0 0.1
        rotation 1 0 0 0
        children [
          HingeJoint {
            device [
              RotationalMotor {
                name "rotational motor 2"
              }
            ]
            endPoint Solid {
              translation 0 0 0.1
              rotation 1 0 0 0
              children [
                HingeJoint {
                  device [
                    RotationalMotor {
                      name "rotational motor 3"
                    }
                  ]
                  endPoint Solid {
                    translation 0 0 0.1
                    rotation 1 0 0 0
                    children [
                      HingeJoint {
                        device [
                          RotationalMotor {
                            name "rotational motor 4"
                          }
                        ]
                        endPoint Solid {
                          translation 0 0 0.1
                          rotation 1 0 0 0
                          children [
                            HingeJoint {
                              device [
                                RotationalMotor {
                                  name "rotational motor 5"
                                }
                              ]
                              endPoint Solid {
                                translation 0 0 0.1
                                rotation 1 0 0 0
                                children [
                                  HingeJoint {
                                    device [
                                      RotationalMotor {
                                        name "rotational motor 6"
                                      }
                                    ]
                                    endPoint Solid {
                                      translation 0 0 0.1
                                      rotation 1 0 0 0
                                      children [
                                        Shape {
                                          geometry Box {
                                            size 0.1 0.05 0.1
                                          }
                                        }
                                      ]
                                      boundingObject Box {
                                        size 0.1 0.05 0.1
                                      }
                                      physics Physics {
                                      }
                                    }
                                  }
                                  Shape {
                                    geometry Box {
                                      size 0.1 0.05 0.1
                                    }
                                  }
                                ]
                                boundingObject Box {
                                  size 0.1 0.05 0.1
                                }
                                physics Physics {
                                }
                              }
                            }
                            Shape {
                              geometry Box {
                                size 0.1 0.05 0.1
                              }
                            }
                          ]
                          boundingObject Box {
                            size 0.1 0.05 0.1
                          }
                          physics Physics {
                          }
                        }
                      }
                      Shape {
                        geometry Box {
                          size 0.1 0.05 0.1
                        }
                      }
                    ]
                    boundingObject Box {
                      size 0.1 0.05 0.1
                    }
                    physics Physics {
                    }
                  }
                }
                Shape {
                  geometry Box {
                    size 0.1 0.05 0.1
                  }
                }
              ]
              boundingObject Box {
                size 0.1 0.05 0.1
              }
              physics Physics {
              }
            }
          }
          Shape {
            geometry Box {
              size 0.1 0.05 0.1
            }
          }
        ]
        boundingObject Box {
          size 0.1 0.05 0.1
        }
        physics Physics {
        }
      }
    }
  ]
  boundingObject Box {
    size 0.1 0.05 0.1
  }
  physics Physics {
  }
  controller "my_controller_2"
  supervisor TRUE
}
