#VRML_SIM R2020a utf8
WorldInfo {
}
Viewpoint {
  orientation 0.18225126326121796 -0.9363870986349542 -0.2999394581406432 4.279521434482395
  position 1.507427682333346 1.0725521485294316 0.2040931345862488
}
TexturedBackground {
}
TexturedBackgroundLight {
}
Windmill {
  translation -26.17 -0.54 20.25
}
Floor {
  translation 0 -0.1 0
}
Robot {
  translation 7.71424e-07 -0.04 0.76
  rotation 0.970418457666435 0.24142911386222196 -6.8045132091282655e-09 4.20424e-06
  children [
    HokuyoUrg04lx {
      translation 1.24311e-06 0.04 -1.44469e-10
      rotation 5.100079999933671e-06 0.9999999999869946 7.192309999906462e-09 -3.141575307179586
      name "sensor"
    }
    Shape {
      appearance Appearance {
        material Material {
          diffuseColor 0.666667 0 0
        }
      }
      geometry Box {
        size 0.1 0.05 0.1
      }
    }
    HingeJoint {
      device [
        RotationalMotor {
          name "rotational motor 1"
        }
      ]
      endPoint Solid {
        translation 0 3.469446951953614e-18 0.09999999999999996
        rotation 1 0 0 0
        children [
          HingeJoint {
            device [
              RotationalMotor {
                name "rotational motor 2"
              }
            ]
            endPoint Solid {
              translation 0 -1.6543612251060553e-24 0.10000000000000002
              rotation 1 0 0 0
              children [
                HingeJoint {
                  device [
                    RotationalMotor {
                      name "rotational motor 3"
                    }
                  ]
                  endPoint Solid {
                    translation 0 -6.938893903907228e-18 0.10000000000000002
                    rotation 1 0 0 0
                    children [
                      HingeJoint {
                        device [
                          RotationalMotor {
                            name "rotational motor 4"
                          }
                        ]
                        endPoint Solid {
                          translation 0 0 0.10000000000000002
                          rotation 1 0 0 0
                          children [
                            HingeJoint {
                              device [
                                RotationalMotor {
                                  name "rotational motor 5"
                                }
                              ]
                              endPoint Solid {
                                translation 0 -1.8418808145348464e-12 0.09999999999999995
                                rotation 1 0 0 0
                                children [
                                  HingeJoint {
                                    device [
                                      RotationalMotor {
                                        name "rotational motor 6"
                                      }
                                    ]
                                    endPoint Solid {
                                      translation 0 1.3877787807814457e-17 0.09999999999999996
                                      rotation 1 0 0 0
                                      children [
                                        Shape {
                                          geometry Box {
                                            size 0.1 0.05 0.1
                                          }
                                        }
                                      ]
                                      boundingObject Box {
                                        size 0.1 0.05 0.1
                                      }
                                      physics Physics {
                                      }
                                    }
                                  }
                                  Shape {
                                    geometry Box {
                                      size 0.1 0.05 0.1
                                    }
                                  }
                                ]
                                boundingObject Box {
                                  size 0.1 0.05 0.1
                                }
                                physics Physics {
                                }
                              }
                            }
                            Shape {
                              geometry Box {
                                size 0.1 0.05 0.1
                              }
                            }
                          ]
                          boundingObject Box {
                            size 0.1 0.05 0.1
                          }
                          physics Physics {
                          }
                        }
                      }
                      Shape {
                        geometry Box {
                          size 0.1 0.05 0.1
                        }
                      }
                    ]
                    boundingObject Box {
                      size 0.1 0.05 0.1
                    }
                    physics Physics {
                    }
                  }
                }
                Shape {
                  geometry Box {
                    size 0.1 0.05 0.1
                  }
                }
              ]
              boundingObject Box {
                size 0.1 0.05 0.1
              }
              physics Physics {
              }
            }
          }
          Shape {
            geometry Box {
              size 0.1 0.05 0.1
            }
          }
        ]
        boundingObject Box {
          size 0.1 0.05 0.1
        }
        physics Physics {
        }
      }
    }
  ]
  boundingObject Box {
    size 0.1 0.05 0.1
  }
  physics Physics {
  }
  controller "my_controller_2"
  supervisor TRUE
}
Solid {
  translation 0 0.18 -4.32
  scale 5 5 5
  children [
    Shape {
      geometry Box {
        size 0.1 0.1 0.1
      }
    }
  ]
  boundingObject Box {
    size 0.1 0.1 0.1
  }
  physics Physics {
  }
}
