#VRML_SIM R2020a utf8
WorldInfo {
}
Viewpoint {
  orientation -0.945333381462096 -0.32353384973193317 -0.040873536317208796 0.5977557970981394
  position -0.1849998176940201 1.3140702940254587 3.2474738506758825
}
TexturedBackground {
}
TexturedBackgroundLight {
}
Windmill {
  translation -26.17 -0.54 20.25
}
Floor {
  translation 0 -0.1 0
}
Robot {
  translation 7.71424e-07 -0.04 0.76
  rotation -0.9714789090127468 -0.23712597779113764 1.6128198489457195e-08 -5.307179586466759e-06
  children [
    SharpGP2Y0A710K0F {
      translation 0.02 0 -0.07
      rotation 0 1 0 1.5708
      name "sensor"
    }
    Shape {
      appearance Appearance {
        material Material {
          diffuseColor 0.666667 0 0
        }
      }
      geometry Box {
        size 0.1 0.05 0.1
      }
    }
    HingeJoint {
      device [
        RotationalMotor {
          name "rotational motor 1"
        }
      ]
      endPoint Solid {
        translation 0 3.469446951953614e-18 0.09999999999999998
        rotation 1 0 0 0
        children [
          HingeJoint {
            device [
              RotationalMotor {
                name "rotational motor 2"
              }
            ]
            endPoint Solid {
              translation 0 -1.6543612251060553e-24 0.09999999999999999
              rotation 1 0 0 0
              children [
                HingeJoint {
                  device [
                    RotationalMotor {
                      name "rotational motor 3"
                    }
                  ]
                  endPoint Solid {
                    translation 0 -6.938893490316922e-18 0.09999999999999999
                    rotation 1 0 0 0
                    children [
                      HingeJoint {
                        device [
                          RotationalMotor {
                            name "rotational motor 4"
                          }
                        ]
                        endPoint Solid {
                          translation 0 0 0.10000000000000006
                          rotation 1 0 0 0
                          children [
                            HingeJoint {
                              device [
                                RotationalMotor {
                                  name "rotational motor 5"
                                }
                              ]
                              endPoint Solid {
                                translation 0 -1.8418808145348464e-12 0.09999999999999996
                                rotation 1 0 0 0
                                children [
                                  HingeJoint {
                                    device [
                                      RotationalMotor {
                                        name "rotational motor 6"
                                      }
                                    ]
                                    endPoint Solid {
                                      translation 0 1.3877787807814457e-17 0.09999999999999996
                                      rotation 1 0 0 0
                                      children [
                                        Shape {
                                          geometry Box {
                                            size 0.1 0.05 0.1
                                          }
                                        }
                                      ]
                                      boundingObject Box {
                                        size 0.1 0.05 0.1
                                      }
                                      physics Physics {
                                      }
                                    }
                                  }
                                  Shape {
                                    geometry Box {
                                      size 0.1 0.05 0.1
                                    }
                                  }
                                ]
                                boundingObject Box {
                                  size 0.1 0.05 0.1
                                }
                                physics Physics {
                                }
                              }
                            }
                            Shape {
                              geometry Box {
                                size 0.1 0.05 0.1
                              }
                            }
                          ]
                          boundingObject Box {
                            size 0.1 0.05 0.1
                          }
                          physics Physics {
                          }
                        }
                      }
                      Shape {
                        geometry Box {
                          size 0.1 0.05 0.1
                        }
                      }
                    ]
                    boundingObject Box {
                      size 0.1 0.05 0.1
                    }
                    physics Physics {
                    }
                  }
                }
                Shape {
                  geometry Box {
                    size 0.1 0.05 0.1
                  }
                }
              ]
              boundingObject Box {
                size 0.1 0.05 0.1
              }
              physics Physics {
              }
            }
          }
          Shape {
            geometry Box {
              size 0.1 0.05 0.1
            }
          }
        ]
        boundingObject Box {
          size 0.1 0.05 0.1
        }
        physics Physics {
        }
      }
    }
  ]
  boundingObject Box {
    size 0.1 0.05 0.1
  }
  physics Physics {
  }
  controller "my_controller_deluxe"
  supervisor TRUE
}
Solid {
  translation 0 0.18 -2.99
  scale 5 5 5
  children [
    Shape {
      geometry Box {
        size 0.1 0.1 0.1
      }
    }
  ]
  boundingObject Box {
    size 0.1 0.1 0.1
  }
  physics Physics {
  }
}
